Workbook
Name CeilingAmountLate: Scenarios!$D$17
Name GainAboveCapitalEarly: Scenarios!$C$14
Name BuyerGross_Late: Scenarios!$D$19
Name ISA_preFloorCapLate: Scenarios!$D$15
Name UpfrontEquityEarly: Scenarios!$C$7
Name VestedEquity_total_Early: Scenarios!$C$6
Name I_monthly: Inputs!$C$7
Name BuyerNetAfterCostsEarly: Scenarios!$C$36
Name CPW_start: Inputs!$C$9
Name TF_early: Inputs!$C$11
Name BuyerImpliedPurchasePriceStandard: Scenarios!$B$43
Name FMV_settlementStandard: Scenarios!$B$9
Name FractPathNetLate: Scenarios!$D$33
Name FractPathGrossEarly: Scenarios!$C$25
Name CumPaidLate: Scenarios!$D$5
Name BuyerGross_Standard: Scenarios!$B$19
Name BuyerSharedFeesAndClosingEarly: Scenarios!$C$27
Name TimingFactorStandard: Scenarios!$B$10
Name BuyerImpliedPurchasePriceLate: Scenarios!$D$43
Name ReShareServicing: Inputs!$C$22
Name IBAStandard: Scenarios!$B$8
Name ExitFeeStandard: Scenarios!$B$24
Name ServicingTotalEarly: Scenarios!$C$23
Name Y_late: Inputs!$C$26
Name BuyerNetAfterCostsStandard: Scenarios!$B$36
Name ServicingTotalLate: Scenarios!$D$23
Name BuyerROIAnnualizedStandard: Scenarios!$B$38
Name ReReferralFlat: Inputs!$C$20
Name CM: Inputs!$C$14
Name BuyerNetProfitAfterFeesStandard: Scenarios!$B$37
Name BuyerSharedFeesAndClosingStandard: Scenarios!$B$27
Name RealtorExitShareLate: Scenarios!$D$31
Name GainAboveCapitalStandard: Scenarios!$B$14
Name ReSharePlatform: Inputs!$C$21
Name VestedEquity_total_Late: Scenarios!$D$6
Name IBALate: Scenarios!$D$8
Name Y_std: Inputs!$C$24
Name ISA_preFloorCapStandard: Scenarios!$B$15
Name FMV_Override: Inputs!$C$5
Name BuyerMoneySavedLate: Scenarios!$D$44
Name ExitFeePct: Inputs!$C$17
Name RealtorPlatformShareStandard: Scenarios!$B$29
Name RealtorTotalShareLate: Scenarios!$D$32
Name RealtorServicingShareLate: Scenarios!$D$30
Name ExitYearEarly: Scenarios!$C$3
Name HomeownerEquityCostStandard: Scenarios!$B$49
Name VestedEquity_totalLate: #REF!
Name FM: Inputs!$C$13
Name UpfrontEquityLate: Scenarios!$D$7
Name RealtorTotalShareEarly: Scenarios!$C$32
Name FMV_settlementEarly: Scenarios!$C$9
Name BaseEquityValueLate: Scenarios!$D$13
Name BaseEquityValueStandard: Scenarios!$B$13
Name ISA_settlementLate: Scenarios!$D$18
Name FractPathGrossLate: Scenarios!$D$25
Name FractPathNetEarly: Scenarios!$C$33
Name ExitFeeLate: Scenarios!$D$24
Name HomeownerCashReceivedStandard: Scenarios!$B$40
Name ExitYearStandard: Scenarios!$B$3
Name MonthIndexEarly: Scenarios!$C$4

Sheet Inputs
A1: Inputs
A2: Section | B2: Variable | C2: Value | D2: Notes
A3: Property | B3: Starting Value (SV) | C3: 600000 | D3: Appraisal/AVM at origination
A4: Property | B4: Annual Appreciation (g) | C4: 0.04 | D4: Decimal (e.g., 0.04 = 4%)
A5: Property | B5: FMV Override (optional) | D5: Optional override for FMV at settlement
A6: Funding | B6: Upfront Payment (I_upfront) | C6: 60000 | D6: Cash at origination
A7: Funding | B7: Monthly Payment (I_monthly) | C7: 2000 | D7: Monthly installment amount
A8: Funding | B8: Number of Payments (N_months) | C8: 72 | D8: Count of monthly payments
A9: Term Sheet | B9: Payback Window Start Year (CPW_start) | C9: 4
A10: Term Sheet | B10: Payback Window End Year (CPW_end) | C10: 8
A11: Term Sheet | B11: Early Discount Factor (TF_early) | C11: 0.9 | D11: Applied if exit before CPW_start
A12: Term Sheet | B12: Late Premium Factor (TF_late) | C12: 1.2 | D12: Applied if exit after CPW_end
A13: Term Sheet | B13: Floor Multiplier (FM) | C13: 1.03 | D13: Minimum multiple of IBA
A14: Term Sheet | B14: Ceiling Multiplier (CM) | C14: 3.25 | D14: Maximum multiple of IBA
A15: Fees / Costs | B15: Platform Fee (FractPath) (PlatformFee) | C15: 5000 | D15: Flat fee
A16: Fees / Costs | B16: Servicing Fee Monthly (ServicingFee) | C16: 49 | D16: Monthly fee
A17: Fees / Costs | B17: Exit Fee % (ExitFeePct) | C17: 0.01 | D17: Percent of ISA
A18: Fees / Costs | B18: Appraisal Fee | C18: 500
A19: Fees / Costs | B19: Expected Closing Costs at Settlement (ClosingCosts) | C19: 0.02 | D19: % of FMV
A20: Realtor Commissions | B20: Realtor Referral Flat (ReReferralFlat) | C20: 2000
A21: Realtor Commissions | B21: Realtor % of Platform Fee (ReSharePlatform) | C21: 0.2 | D21: Decimal share
A22: Realtor Commissions | B22: Realtor % of Servicing Fees (ReShareServicing) | C22: 0 | D22: Decimal share
A23: Realtor Commissions | B23: Realtor % of Exit Fee (ReShareExit) | C23: 0.15 | D23: Decimal share
A24: Scenario timing | B24: Standard Exit Year (Y_std) | C24: 7 | D24: Year expected to sell
A25: Scenario timing | B25: Early Exit Year (Y_early) | C25: 2 | D25: Early sell year
A26: Scenario timing | B26: Late Exit Year (Y_late) | C26: 12 | D26: Late sell year
A27: Governance / Toggles | B27: Downside Mode (DownsideMode) | C27: HARD_FLOOR | D27: HARD_FLOOR | NO_FLOOR
A28: Governance / Toggles | B28: Buyback Pricing Mode (BuybackPricing) | C28: ISA_PRO_RATA | D28: ISA_PRO_RATA (default)
A29: Duration Protection | B29: Contract Maturity (Years) (MaturityYears) | C29: 30 | D29: Hard maturity cap
A30: Duration Protection | B30: Liquidity Trigger Offset (Years) (LiquidityOffsetYears) | C30: 5 | D30: Default = CPW_end + offset
A31: Duration Protection | B31: Liquidity Trigger Year (LiquidityTriggerYear) | C31: =CPW_end + LiquidityOffsetYears | D31: Computed
A32: Duration Protection | B32: Minimum Hold (Years) (MinHoldYears) | C32: 2 | D32: Buyback not allowed before this
A33: Duration Protection | B33: Buyback Allowed (BuybackAllowed) | C33: TRUE | D33: Mandatory allowed = TRUE
A34: Options | B34: Uses Realtor? (UseRealtor) | C34: TRUE | D34: TRUE/FALSE
A35: Options | B35: Use Appraisal Fee? (UseAppraisalFee) | C35: TRUE | D35: TRUE/FALSE

Sheet Schedule
A1: Schedule
A2: Month | B2: Payment | C2: Value_t | D2: EquityBought_t | E2: CumPaid | F2: CumEquity | H2: UpfrontEquity (reference)
A3: 1 | B3: =IF(A3<=N_months, I_monthly, 0) | C3: =SV*(1+g)^(A3/12) | D3: =IF(B3=0,0,B3/C3) | E3: =SUM($B$3:B3) | F3: =(SUM($D$3:D3)+$H$3) | H3: =IF(I_upfront=0,0,I_upfront/SV)
A4: 2 | B4: =IF(A4<=N_months, I_monthly, 0) | C4: =SV*(1+g)^(A4/12) | D4: =IF(B4=0,0,B4/C4) | E4: =SUM($B$3:B4) | F4: =(SUM($D$3:D4)+$H$3)
A5: 3 | B5: =IF(A5<=N_months, I_monthly, 0) | C5: =SV*(1+g)^(A5/12) | D5: =IF(B5=0,0,B5/C5) | E5: =SUM($B$3:B5) | F5: =(SUM($D$3:D5)+$H$3)
A6: 4 | B6: =IF(A6<=N_months, I_monthly, 0) | C6: =SV*(1+g)^(A6/12) | D6: =IF(B6=0,0,B6/C6) | E6: =SUM($B$3:B6) | F6: =(SUM($D$3:D6)+$H$3)
A7: 5 | B7: =IF(A7<=N_months, I_monthly, 0) | C7: =SV*(1+g)^(A7/12) | D7: =IF(B7=0,0,B7/C7) | E7: =SUM($B$3:B7) | F7: =(SUM($D$3:D7)+$H$3)
A8: 6 | B8: =IF(A8<=N_months, I_monthly, 0) | C8: =SV*(1+g)^(A8/12) | D8: =IF(B8=0,0,B8/C8) | E8: =SUM($B$3:B8) | F8: =(SUM($D$3:D8)+$H$3)
A9: 7 | B9: =IF(A9<=N_months, I_monthly, 0) | C9: =SV*(1+g)^(A9/12) | D9: =IF(B9=0,0,B9/C9) | E9: =SUM($B$3:B9) | F9: =(SUM($D$3:D9)+$H$3)
A10: 8 | B10: =IF(A10<=N_months, I_monthly, 0) | C10: =SV*(1+g)^(A10/12) | D10: =IF(B10=0,0,B10/C10) | E10: =SUM($B$3:B10) | F10: =(SUM($D$3:D10)+$H$3)
A11: 9 | B11: =IF(A11<=N_months, I_monthly, 0) | C11: =SV*(1+g)^(A11/12) | D11: =IF(B11=0,0,B11/C11) | E11: =SUM($B$3:B11) | F11: =(SUM($D$3:D11)+$H$3)
A12: 10 | B12: =IF(A12<=N_months, I_monthly, 0) | C12: =SV*(1+g)^(A12/12) | D12: =IF(B12=0,0,B12/C12) | E12: =SUM($B$3:B12) | F12: =(SUM($D$3:D12)+$H$3)
A13: 11 | B13: =IF(A13<=N_months, I_monthly, 0) | C13: =SV*(1+g)^(A13/12) | D13: =IF(B13=0,0,B13/C13) | E13: =SUM($B$3:B13) | F13: =(SUM($D$3:D13)+$H$3)
A14: 12 | B14: =IF(A14<=N_months, I_monthly, 0) | C14: =SV*(1+g)^(A14/12) | D14: =IF(B14=0,0,B14/C14) | E14: =SUM($B$3:B14) | F14: =(SUM($D$3:D14)+$H$3)
A15: 13 | B15: =IF(A15<=N_months, I_monthly, 0) | C15: =SV*(1+g)^(A15/12) | D15: =IF(B15=0,0,B15/C15) | E15: =SUM($B$3:B15) | F15: =(SUM($D$3:D15)+$H$3)
... A33: 31 | B33: =IF(A33<=N_months, I_monthly, 0) | C33: =SV*(1+g)^(A33/12) | D33: =IF(B33=0,0,B33/C33) | E33: =SUM($B$3:B33) | F33: =(SUM($D$3:D33)+$H$3)
A34: 32 | B34: =IF(A34<=N_months, I_monthly, 0) | C34: =SV*(1+g)^(A34/12) | D34: =IF(B34=0,0,B34/C34) | E34: =SUM($B$3:B34) | F34: =(SUM($D$3:D34)+$H$3) | G34: =sum(D3:D38)
A35: 33 | B35: =IF(A35<=N_months, I_monthly, 0) | C35: =SV*(1+g)^(A35/12) | D35: =IF(B35=0,0,B35/C35) | E35: =SUM($B$3:B35) | F35: =(SUM($D$3:D35)+$H$3)
A36: 34 | B36: =IF(A36<=N_months, I_monthly, 0) | C36: =SV*(1+g)^(A36/12) | D36: =IF(B36=0,0,B36/C36) | E36: =SUM($B$3:B36) | F36: =(SUM($D$3:D36)+$H$3)
A37: 35 | B37: =IF(A37<=N_months, I_monthly, 0) | C37: =SV*(1+g)^(A37/12) | D37: =IF(B37=0,0,B37/C37) | E37: =SUM($B$3:B37) | F37: =(SUM($D$3:D37)+$H$3)
A38: 36 | B38: =IF(A38<=N_months, I_monthly, 0) | C38: =SV*(1+g)^(A38/12) | D38: =IF(B38=0,0,B38/C38) | E38: =SUM($B$3:B38) | F38: =(SUM($D$3:D38)+$H$3)
A39: 37 | B39: =IF(A39<=N_months, I_monthly, 0) | C39: =SV*(1+g)^(A39/12) | D39: =IF(B39=0,0,B39/C39) | E39: =SUM($B$3:B39) | F39: =(SUM($D$3:D39)+$H$3)
A40: 38 | B40: =IF(A40<=N_months, I_monthly, 0) | C40: =SV*(1+g)^(A40/12) | D40: =IF(B40=0,0,B40/C40) | E40: =SUM($B$3:B40) | F40: =(SUM($D$3:D40)+$H$3)
A41: 39 | B41: =IF(A41<=N_months, I_monthly, 0) | C41: =SV*(1+g)^(A41/12) | D41: =IF(B41=0,0,B41/C41) | E41: =SUM($B$3:B41) | F41: =(SUM($D$3:D41)+$H$3)
A42: 40 | B42: =IF(A42<=N_months, I_monthly, 0) | C42: =SV*(1+g)^(A42/12) | D42: =IF(B42=0,0,B42/C42) | E42: =SUM($B$3:B42) | F42: =(SUM($D$3:D42)+$H$3)
A43: 41 | B43: =IF(A43<=N_months, I_monthly, 0) | C43: =SV*(1+g)^(A43/12) | D43: =IF(B43=0,0,B43/C43) | E43: =SUM($B$3:B43) | F43: =(SUM($D$3:D43)+$H$3)
A44: 42 | B44: =IF(A44<=N_months, I_monthly, 0) | C44: =SV*(1+g)^(A44/12) | D44: =IF(B44=0,0,B44/C44) | E44: =SUM($B$3:B44) | F44: =(SUM($D$3:D44)+$H$3)
A45: 43 | B45: =IF(A45<=N_months, I_monthly, 0) | C45: =SV*(1+g)^(A45/12) | D45: =IF(B45=0,0,B45/C45) | E45: =SUM($B$3:B45) | F45: =(SUM($D$3:D45)+$H$3)
A46: 44 | B46: =IF(A46<=N_months, I_monthly, 0) | C46: =SV*(1+g)^(A46/12) | D46: =IF(B46=0,0,B46/C46) | E46: =SUM($B$3:B46) | F46: =(SUM($D$3:D46)+$H$3)
... A242: 240 | B242: =IF(A242<=N_months, I_monthly, 0) | C242: =SV*(1+g)^(A242/12) | D242: =IF(B242=0,0,B242/C242) | E242: =SUM($B$3:B242) | F242: =(SUM($D$3:D242)+$H$3)

Sheet Scenarios
A1: Scenarios
A2: Metric | B2: Standard | C2: Early | D2: Late | E2: Notes
A3: Exit Year | B3: =Y_std | C3: =Y_early | D3: =Y_late | E3: Scenario years
A4: MonthIndex | B4: =MIN(ROUND(ExitYearStandard*12,0),240) | C4: =MIN(ROUND(ExitYearEarly*12,0),240) | D4: =MIN(ROUND(ExitYearLate*12,0),240) | E4: Month index for schedule lookups
A5: CumPaid | B5: {=INDEX(Schedule!E:E, MonthIndexStandard+1)} | C5: {=INDEX(Schedule!E:E, MonthIndexEarly+1)} | D5: {=INDEX(Schedule!E:E, MonthIndexLate+1)} | E5: Cumulative payments made so far (installments only).
A6: VestedEquity_total | B6: {=INDEX(Schedule!F:F, B4+1)} | C6: {=INDEX(Schedule!F:F, C4+1)} | D6: {=INDEX(Schedule!F:F, MonthIndexLate+1)} | E6: Total equity earned from installments so far.
A7: UpfrontEquity | B7: =IF(I_upfront=0,0,I_upfront/SV) | C7: =IF(I_upfront=0,0,I_upfront/SV) | D7: =IF(I_upfront=0,0,I_upfront/SV) | E7: Equity purchased from the upfront payment.
A8: IBA_Buyer_paid_to_date | B8: =I_upfront + CumPaidStandard | C8: =I_upfront + CumPaidEarly | D8: =I_upfront + CumPaidLate | E8: Investor Base Amount. Cash actually invested to date (not committed capital)
A9: FMV_settlement | B9: =IF(FMV_Override<>"", FMV_Override, SV*(1+g)^B3) | C9: =IF(FMV_Override<>"", FMV_Override, SV*(1+g)^C3) | D9: =IF(FMV_Override<>"", FMV_Override, SV*(1+g)^D3) | E9: Fair Market Value of the home at settlement.
A10: TF | B10: =IF(B3<CPW_start, TF_early, IF(B3>CPW_end, TF_late, 1)) | C10: =IF(C3<CPW_start, TF_early, IF(C3>CPW_end, TF_late, 1)) | D10: =IF(D3<CPW_start, TF_early, IF(D3>CPW_end, TF_late, 1)) | E10: TF (Timing Factor) A multiplier that adjusts payout based on when the deal ends.
A12: BUYER CONTRACT RETURN
A13: BaseEquityValue | B13: =FMV_settlementStandard * VestedEquity_total_Standard | C13: =FMV_settlementEarly * VestedEquity_total_Early | D13: =FMV_settlementLate * VestedEquity_total_Late | E13: Value of buyer’s vested equity at FMV (no timing, no floor/ceiling).
A14: GainAboveCapital | B14: =(MAX(0,BaseEquityValueStandard-IBAStandard)) | C14: =(MAX(0,BaseEquityValueEarly-IBAEarly)) | D14: =(MAX(0,BaseEquityValueLate-IBALate)) | E14: UIA adjusted by early/late timing factor (TF).
A15: ISA_preFloorCap | B15: =IBAStandard + (GainAboveCapitalStandard * TimingFactorStandard) | C15: =IBAEarly + (GainAboveCapitalEarly * TimingFactorEarly) | D15: =IBALate + (GainAboveCapitalLate * TimingFactorLate)
A16: FloorAmount | B16: =IBAStandard* FM | C16: =IBAEarly * FM | D16: =IBALate * FM | E16: Minimum payout = Floor multiple × total buyer cash invested (IBA). Floors and timing factors are contractual settlement terms, not guaranteed returns or interest.
A17: CeilingAmount | B17: =IBAStandard * CM | C17: =IBAEarly * CM | D17: =IBALate * CM | E17: Maximum payout = Ceiling multiple × total buyer cash invested (IBA).
A18: ISA_settlement | B18: =IF(DownsideMode="HARD_FLOOR",MIN(MAX(ISA_preFloorCapStandard, FloorAmountStandard), CeilingAmountStandard),MIN(ISA_preFloorCapStandard, CeilingAmountStandard)) | C18: =IF(DownsideMode="HARD_FLOOR",MIN(MAX(ISA_preFloorCapEarly, FloorAmountEarly), CeilingAmountEarly),MIN(ISA_preFloorCapEarly, CeilingAmountEarly)) | D18: =IF(DownsideMode="HARD_FLOOR",MIN(MAX(ISA_preFloorCapLate, FloorAmountLate), CeilingAmountLate),MIN(ISA_preFloorCapLate, CeilingAmountLate)) | E18: Final contract payout to buyer for their equity (after timing, within floor/ceiling).
A19: Gross Profit | B19: =ISA_settlementStandard-IBAStandard | C19: =ISA_settlementEarly-IBAEarly | D19: =ISA_settlementLate-IBALate | E19: Buyer contract profit before any shared fees = ISA − IBA.
A20: NetAfterSharedFees | B20: =BuyerGross_Standard-BuyerSharedFeesAndClosingStandard | C20: =BuyerGross_Early-BuyerSharedFeesAndClosingEarly | D20: =BuyerGross_Late-BuyerSharedFeesAndClosingLate
A22: FEE SHARING & PLATFORM ECONOMICS
A23: ServicingTotal | B23: =ServicingFee * ROUND(ExitYearStandard*12,0) | C23: =ServicingFee * ROUND(ExitYearEarly*12,0) | D23: =ServicingFee * ROUND(ExitYearLate*12,0) | E23: Total servicing fees collected over time.
A24: ExitFee | B24: =ExitFeePct * ISA_settlementStandard | C24: =ExitFeePct * ISA_settlementEarly | D24: =ExitFeePct * ISA_settlementLate | E24: Transaction fee charged at settlement.
A25: FractPathGross | B25: =PlatformFee + ServicingTotalStandard + ExitFeeStandard+ AppraisalFee | C25: =PlatformFee + ServicingTotalEarly + ExitFeeEarly+AppraisalFee | D25: =PlatformFee + ServicingTotalLate + ExitFeeLate+AppraisalFee | E25: All revenue FractPath generates from this deal.
A26: TotalCFeesAndClosing | B26: =(ClosingCosts*FMV_settlementStandard) + FractPathGrossStandard | C26: =(ClosingCosts*FMV_settlementEarly) + FractPathGrossEarly | D26: =(ClosingCosts*FMV_settlementLate) + FractPathGrossLate | E26: Total platform, servicing, exit fee, and closing costs for this settlement.”
A27: BuyerSharedFeesAndClosing | B27: =TotalClosingAndFractpathGrossStandard*(VestedEquity_total_Standard) | C27: =TotalClosingAndFractpathGrossEarly*(VestedEquity_total_Early) | D27: =TotalClosingAndFractpathGrossLate*(VestedEquity_total_Late) | E27: Buyer’s share of total fees/costs, allocated by equity share.
A28: SellerSharedFeesAndClosing | B28: =TotalClosingAndFractpathGrossStandard-BuyerSharedFeesAndClosingStandard | C28: =TotalClosingAndFractpathGrossEarly-BuyerSharedFeesAndClosingEarly | D28: =TotalClosingAndFractpathGrossLate-BuyerSharedFeesAndClosingLate | E28: Seller’s share of total fees/costs, allocated by equity share.
A29: RealtorPlatformShare | B29: =ReSharePlatform * PlatformFee | C29: =ReSharePlatform * PlatformFee | D29: =ReSharePlatform * PlatformFee | E29: Realtor’s share of the platform fee.
A30: RealtorServicingShare | B30: =ReShareServicing * ServicingTotalStandard | C30: =ReShareServicing * ServicingTotalEarly | D30: =ReShareServicing * ServicingTotalLate | E30: Realtor’s share of servicing fees.
A31: RealtorExitShare | B31: =ReShareExit * ExitFeeStandard | C31: =ReShareExit * ExitFeeEarly | D31: =ReShareExit * ExitFeeLate | E31: Realtor’s share of the exit fee.
A32: RealtorTotalShare | B32: =ReReferralFlat + RealtorPlatformShareStandard + RealtorServicingShareStandard + RealtorExitShareStandard | C32: =ReReferralFlat + RealtorPlatformShareEarly + RealtorServicingShareEarly + RealtorExitShareEarly | D32: =ReReferralFlat + RealtorPlatformShareLate + RealtorServicingShareLate + RealtorExitShareLate | E32: Total paid to realtor from platform, servicing, and exit fee.
A33: FractPathNet | B33: =FractPathGrossStandard - RealtorTotalShareStandard | C33: =FractPathGrossEarly - RealtorTotalShareEarly | D33: =FractPathGrossLate - RealtorTotalShareLate | E33: FractPath revenue after paying realtor (net platform economics).
A35: NET CASH TO BUYER & HOMEOWNER
A36: BuyerNetAfterCosts | B36: =ISA_settlementStandard-BuyerSharedFeesAndClosingStandard | C36: =ISA_settlementEarly-BuyerSharedFeesAndClosingEarly | D36: =ISA_settlementLate-BuyerSharedFeesAndClosingLate | E36: Buyer cash received after ISA and after their share of all fees/costs.
A37: BuyerNetProfitAfterFees | B37: =BuyerNetAfterCostsStandard - IBAStandard | C37: =BuyerNetAfterCostsEarly - IBAEarly | D37: =BuyerNetAfterCostsLate - IBALate | E37: Buyer profit = BuyerNetAfterCosts − IBA (fully loaded, after fees).
A38: BuyerROIAnnualized | B38: =(BuyerNetProfitAfterFeesStandard/(IBAStandard)/ExitYearStandard) | C38: =(BuyerNetProfitAfterFeesEarly/(IBAEarly)/ExitYearEarly) | D38: =(BuyerNetProfitAfterFeesLate/(IBALate)/ExitYearLate) | E38: The amount of net proceeds from deal divided by total paid
A39: HomeownerNetAfterCosts | B39: =FMV_settlementStandard-BuyerNetAfterCostsStandard-SellerSharedFeesAndClosingStandard | C39: =FMV_settlementEarly-BuyerNetAfterCostsEarly-SellerSharedFeesAndClosingEarly | D39: =FMV_settlementLate-BuyerNetAfterCostsLate-SellerSharedFeesAndClosingLate | E39: Homeowner sale proceeds after their share of all fees/costs.
A40: HomeownerCashReceived | B40: =HomeownerNetAfterCostsStandard+IBAStandard | C40: =HomeownerNetAfterCostsEarly+IBAEarly | D40: =HomeownerNetAfterCostsLate+IBALate | E40: Total cash to homeowner with deal = upfront + monthly payments + HomeownerNetAfterCosts.
A42: BUYER REMAINING EQUITY BARGAIN
A43: BuyerImpliedPurchasePrice | B43: =IBAStandard / VestedEquity_total_Standard | C43: =IBAEarly / VestedEquity_total_Early | D43: =IBALate / VestedEquity_total_Late | E43: This is the price of the remaining equity for the buyer to purchase
A44: BuyerDiscountVsMarket | B44: =IF(FMV_settlementStandard=0,"", 1 - (BuyerImpliedPurchasePriceStandard / FMV_settlementStandard)) | C44: =IF(FMV_settlementEarly=0,"", 1 - (BuyerImpliedPurchasePriceEarly / FMV_settlementEarly)) | D44: =IF(FMV_settlementLate=0,"", 1 - (BuyerImpliedPurchasePriceLate / FMV_settlementLate)) | E44: This is the money the buyer saved by purchasing early equity rather than waiting
...

Sheet Summary
A1: Summary
A2: Party / Metric | B2: Standard | C2: Early | D2: Late
A3: Buyer — Total Invested | B3: =I_upfront + CumPaidStandard | C3: =I_upfront + CumPaidEarly | D3: =I_upfront + CumPaidLate
A4: Buyer — Settlement Received (ISA) | B4: =ISA_settlementStandard | C4: =ISA_settlementEarly | D4: =ISA_settlementLate
A5: Buyer — Profit (Net Cash) | B5: =BuyerNetProfitAfterFeesStandard | C5: =BuyerNetProfitAfterFeesEarly | D5: =BuyerNetProfitAfterFeesLate
A6: Buyer — Multiple (ISA / Invested) | B6: =IF(B3=0,"",B4/B3) | C6: =IF(C3=0,"",C4/C3) | D6: =IF(D3=0,"",D4/D3)
A8: Homeowner — Cash Received To Date | B8: =I_upfront + CumPaidStandard | C8: =I_upfront + CumPaidEarly | D8: =I_upfront + CumPaidLate
A9: Homeowner — Total Paid at Settlement | B9: =FMV_settlementStandard-HomeownerNetAfterCostsStandard | C9: =FMV_settlementEarly-HomeownerNetAfterCostsEarly | D9: =FMV_settlementLate-HomeownerNetAfterCostsLate
A10: Homeowner — Net Financing Impact | B10: =HomeownerCashReceivedStandard | C10: =HomeownerCashReceivedEarly | D10: =HomeownerCashReceivedLate
A12: Realtor — Total | B12: =RealtorTotalShareStandard | C12: =RealtorTotalShareEarly | D12: =RealtorTotalShareLate
A14: FractPath — Gross | B14: =FractPathGrossStandard | C14: =FractPathGrossEarly | D14: =FractPathGrossLate
A15: FractPath — Net after Realtor | B15: =FractPathNetStandard | C15: =FractPathNetEarly | D15: =FractPathNetLate
A17: Governance / Toggles
A18: Downside Mode | B18: =DownsideMode
A19: Buyback Pricing | B19: =BuybackPricing
A20: Maturity (Years) | B20: =MaturityYears
A21: Liquidity Trigger Year | B21: =LiquidityTriggerYear
A22: Min Hold (Years) | B22: =MinHoldYears
